<?xml version="1.0" ?>
<!-- =================================================================================== -->
<!-- |    This document was autogenerated by xacro from sherpa_busy_genius.xacro       | -->
<!-- |    EDITING THIS FILE BY HAND IS NOT RECOMMENDED                                 | -->
<!-- =================================================================================== -->
<robot name="busy_genius" xmlns:xacro="http://ros.org/wiki/xacro">
 
 <material name="Blue">
    <color rgba="0.0 0.0 0.8 1.0"/>
  </material>
  <material name="Green">
    <color rgba="0.0 0.8 0.0 1.0"/>
  </material>
  <material name="Grey">
    <color rgba="0.7 0.7 0.7 1.0"/>
  </material>
  <material name="Grey2">
    <color rgba="0.9 0.9 0.9 1.0"/>
  </material>
  <material name="Red">
    <color rgba="0.8 0.0 0.0 1.0"/>
  </material>
  <material name="White">
    <color rgba="1.0 1.0 1.0 1.0"/>
  </material>
  <material name="Black">
    <color rgba="0.1 0.1 0.1 1.0"/>
  </material>
  <material name="LightGrey">
    <color rgba="0.6 0.6 0.6 1.0"/>
  </material>

  <link name="world">
    </link>
  <link name="pelvis_x">
    <inertial>
      <mass value="1"/>
      <origin xyz="0 0 0"/>
      <inertia ixx="1.0" ixy="0.0" ixz="0.0" iyy="1.0" iyz="0.0" izz="1.0"/>
    </inertial>
  </link>
  <link name="pelvis_y">
    <inertial>
      <mass value="1"/>
      <origin xyz="0 0 0"/>
      <inertia ixx="1.0" ixy="0.0" ixz="0.0" iyy="1.0" iyz="0.0" izz="1.0"/>
    </inertial>
  </link>
  <link name="pelvis_z">
    <inertial>
      <mass value="1"/>
      <origin xyz="0 0 0"/>
      <inertia ixx="1.0" ixy="0.0" ixz="0.0" iyy="1.0" iyz="0.0" izz="1.0"/>
    </inertial>
    <visual>
      <origin rpy="0 0 0" xyz="0 0 0"/>
      <geometry>
        <mesh filename="package://sherpa_spatial_relations/meshes/Hips.dae"/>
      </geometry>
    <material name="Blue"/>
    </visual>
    <collision>
      <origin rpy="0 0 0" xyz="0 0 0"/>
      <geometry>
        <mesh filename="package://sherpa_spatial_relations/meshes/Hips.dae.stl"/>
      </geometry>
    </collision>
  </link>
  <link name="l5_x">
    <inertial>
      <mass value="1"/>
      <origin xyz="0 0 0"/>
      <inertia ixx="1.0" ixy="0.0" ixz="0.0" iyy="1.0" iyz="0.0" izz="1.0"/>
    </inertial>
  </link>
  <link name="l5_y">
    <inertial>
      <mass value="1"/>
      <origin xyz="0 0 0"/>
      <inertia ixx="1.0" ixy="0.0" ixz="0.0" iyy="1.0" iyz="0.0" izz="1.0"/>
    </inertial>
  </link>
  <link name="l5_z">
    <inertial>
      <mass value="1"/>
      <origin xyz="0 0 0"/>
      <inertia ixx="1.0" ixy="0.0" ixz="0.0" iyy="1.0" iyz="0.0" izz="1.0"/>
    </inertial>
    <visual>
      <origin rpy="0 0 0" xyz="0 0 0"/>
      <geometry>
        <mesh filename="package://sherpa_spatial_relations/meshes/Body1.dae" />
      </geometry>
  <material name="Red"/>
    </visual>
    <collision>
      <origin rpy="0 0 0" xyz="0 0 0"/>
      <geometry>
        <mesh filename="package://sherpa_spatial_relations/meshes/Body1.dae.stl"/>
      </geometry>
    </collision>
  </link>
  <link name="l3_x">
    <inertial>
      <mass value="1"/>
      <origin xyz="0 0 0"/>
      <inertia ixx="1.0" ixy="0.0" ixz="0.0" iyy="1.0" iyz="0.0" izz="1.0"/>
    </inertial>
  </link>
  <link name="l3_y">
    <inertial>
      <mass value="1"/>
      <origin xyz="0 0 0"/>
      <inertia ixx="1.0" ixy="0.0" ixz="0.0" iyy="1.0" iyz="0.0" izz="1.0"/>
    </inertial>
  </link>
  <link name="l3_z">
    <inertial>
      <mass value="1"/>
      <origin xyz="0 0 0"/>
      <inertia ixx="1.0" ixy="0.0" ixz="0.0" iyy="1.0" iyz="0.0" izz="1.0"/>
    </inertial>
    <visual>
      <origin rpy="0 0 0" xyz="0 0 0"/>
      <geometry>
        <mesh filename="package://sherpa_spatial_relations/meshes/Body2.dae" />
      </geometry>
     <material name="Red"/>
    </visual>
    <collision>
      <origin rpy="0 0 0" xyz="0 0 0"/>
      <geometry>
        <mesh filename="package://sherpa_spatial_relations/meshes/Body2.dae.stl"/>
      </geometry>
    </collision>
  </link>
  <link name="t12_x">
    <inertial>
      <mass value="1"/>
      <origin xyz="0 0 0"/>
      <inertia ixx="1.0" ixy="0.0" ixz="0.0" iyy="1.0" iyz="0.0" izz="1.0"/>
    </inertial>
  </link>
  <link name="t12_y">
    <inertial>
      <mass value="1"/>
      <origin xyz="0 0 0"/>
      <inertia ixx="1.0" ixy="0.0" ixz="0.0" iyy="1.0" iyz="0.0" izz="1.0"/>
    </inertial>
  </link>
  <link name="t12_z">
    <inertial>
      <mass value="1"/>
      <origin xyz="0 0 0"/>
      <inertia ixx="1.0" ixy="0.0" ixz="0.0" iyy="1.0" iyz="0.0" izz="1.0"/>
    </inertial>
    <visual>
      <origin rpy="0 0 0" xyz="0 0 0"/>
      <geometry>
        <mesh filename="package://sherpa_spatial_relations/meshes/Body3.dae" />
      </geometry>
      <material name="Red"/>
    </visual>
    <collision>
      <origin rpy="0 0 0" xyz="0 0 0"/>
      <geometry>
        <mesh filename="package://sherpa_spatial_relations/meshes/Body3.dae.stl"/>
      </geometry>
    </collision>
  </link>
  <link name="t8_x">
    <inertial>
      <mass value="1"/>
      <origin xyz="0 0 0"/>
      <inertia ixx="1.0" ixy="0.0" ixz="0.0" iyy="1.0" iyz="0.0" izz="1.0"/>
    </inertial>
  </link>
  <link name="t8_y">
    <inertial>
      <mass value="1"/>
      <origin xyz="0 0 0"/>
      <inertia ixx="1.0" ixy="0.0" ixz="0.0" iyy="1.0" iyz="0.0" izz="1.0"/>
    </inertial>
  </link>
  <link name="t8_z">
    <inertial>
      <mass value="1"/>
      <origin xyz="0 0 0"/>
      <inertia ixx="1.0" ixy="0.0" ixz="0.0" iyy="1.0" iyz="0.0" izz="1.0"/>
    </inertial>
    <visual>
      <origin rpy="0 0 0" xyz="0 0 0"/>
      <geometry>
        <mesh filename="package://sherpa_spatial_relations/meshes/Body4.dae"/>
      </geometry>
     <material name="Red"/>
    </visual>
    <collision>
      <origin rpy="0 0 0" xyz="0 0 0"/>
      <geometry>
        <mesh filename="package://sherpa_spatial_relations/meshes/Body4.dae.stl"/>
      </geometry>
    </collision>
  </link>
  <link name="neck_x">
    <inertial>
      <mass value="1"/>
      <origin xyz="0 0 0"/>
      <inertia ixx="1.0" ixy="0.0" ixz="0.0" iyy="1.0" iyz="0.0" izz="1.0"/>
    </inertial>
  </link>
  <link name="neck_y">
    <inertial>
      <mass value="1"/>
      <origin xyz="0 0 0"/>
      <inertia ixx="1.0" ixy="0.0" ixz="0.0" iyy="1.0" iyz="0.0" izz="1.0"/>
    </inertial>
  </link>
  <link name="neck_z">
    <inertial>
      <mass value="1"/>
      <origin xyz="0 0 0"/>
      <inertia ixx="1.0" ixy="0.0" ixz="0.0" iyy="1.0" iyz="0.0" izz="1.0"/>
    </inertial>
    <visual>
      <origin rpy="0 0 0" xyz="0 0 0"/>
      <geometry>
        <mesh filename="package://sherpa_spatial_relations/meshes/Neck.dae"/>
      </geometry>
  <material name="LightGrey"/>
    </visual>
    <collision>
      <origin rpy="0 0 0" xyz="0 0 0"/>
      <geometry>
        <mesh filename="package://sherpa_spatial_relations/meshes/Neck.dae.stl"/>
      </geometry>
    </collision>
  </link>

  <link name="head_x">
    <inertial>
      <mass value="1"/>
      <origin xyz="0 0 0"/>
      <inertia ixx="1.0" ixy="0.0" ixz="0.0" iyy="1.0" iyz="0.0" izz="1.0"/>
    </inertial>
  </link>
  <link name="head_y">
    <inertial>
      <mass value="1"/>
      <origin xyz="0 0 0"/>
      <inertia ixx="1.0" ixy="0.0" ixz="0.0" iyy="1.0" iyz="0.0" izz="1.0"/>
    </inertial>
  </link>
  <link name="head_z">
    <inertial>
      <mass value="1"/>
      <origin xyz="0 0 0"/>
      <inertia ixx="1.0" ixy="0.0" ixz="0.0" iyy="1.0" iyz="0.0" izz="1.0"/>
    </inertial>
    <visual>
      <origin rpy="0 0 0" xyz="0 0 0"/>
      <geometry>
        <mesh filename="package://sherpa_spatial_relations/meshes/Head.dae"/>
      </geometry>
  <material name="Blue"/>
    </visual>
    <collision>
      <origin rpy="0 0 0" xyz="0 0 0"/>
      <geometry>
        <mesh filename="package://sherpa_spatial_relations/meshes/Head.dae.stl"/>
      </geometry>
    </collision>
  </link>
  <joint name="pelvis_joint_x" type="revolute">
    <parent link="world"/>
    <child link="pelvis_x"/>
    <origin rpy="1.5707 0 0" xyz="0 0 0.91"/>
    <axis xyz="1 0 0"/>
    <dynamics damping="0.7"/>
    <limit effort="100" lower="-2" upper="2" velocity="10.0"/>
  </joint>
  <transmission name="trans_pelvis_x">
    <type>transmission_interface/SimpleTransmission</type>
    <joint name="pelvis_joint_x"/>
    <actuator name="pelvis_motor_x">
      <hardwareInterface>PositionJointInterface</hardwareInterface>
      <mechanicalReduction>1</mechanicalReduction>
    </actuator>
  </transmission>
  <joint name="pelvis_joint_z" type="revolute">
    <parent link="pelvis_x"/>
    <child link="pelvis_z"/>
    <origin rpy="0 0 0" xyz="0 0 0"/>
    <axis xyz="0 0 1"/>
    <dynamics damping="0.7"/>
    <limit effort="100" lower="-2" upper="2" velocity="10.0"/>
  </joint>
  <transmission name="trans_{name}_z">
    <type>transmission_interface/SimpleTransmission</type>
    <joint name="pelvis_joint_z"/>
    <actuator name="pelvis_motor_z">
      <hardwareInterface>PositionJointInterface</hardwareInterface>
      <mechanicalReduction>1</mechanicalReduction>
    </actuator>
  </transmission>
  <joint name="pelvis_joint_y" type="revolute">
    <parent link="pelvis_z"/>
    <child link="pelvis_y"/>
    <origin rpy="0 0 0" xyz="0 0 0"/>
    <axis xyz="0 1 0"/>
    <dynamics damping="0.7"/>
    <limit effort="100" lower="-2" upper="2" velocity="10.0"/>
  </joint>
  <transmission name="trans_pelvis_y">
    <type>transmission_interface/SimpleTransmission</type>
    <joint name="pelvis_joint_y"/>
    <actuator name="pelvis_motor_y">
      <hardwareInterface>PositionJointInterface</hardwareInterface>
      <mechanicalReduction>1</mechanicalReduction>
    </actuator>
  </transmission>
  <joint name="l5_joint_x" type="revolute">
    <parent link="pelvis_y"/>
    <child link="l5_x"/>
    <origin rpy="0 0 0" xyz="0 0.1 0 "/>
    <axis xyz="1 0 0"/>
    <dynamics damping="0.7"/>
    <limit effort="100" lower="-2" upper="2" velocity="10.0"/>
  </joint>
  <transmission name="trans_l5_x">
    <type>transmission_interface/SimpleTransmission</type>
    <joint name="l5_joint_x"/>
    <actuator name="l5_motor_x">
      <hardwareInterface>PositionJointInterface</hardwareInterface>
      <mechanicalReduction>1</mechanicalReduction>
    </actuator>
  </transmission>
  <joint name="l5_joint_z" type="revolute">
    <parent link="l5_x"/>
    <child link="l5_z"/>
    <origin rpy="0 0 0" xyz="0 0 0"/>
    <axis xyz="0 0 1"/>
    <dynamics damping="0.7"/>
    <limit effort="100" lower="-2" upper="2" velocity="10.0"/>
  </joint>
  <transmission name="trans_{name}_z">
    <type>transmission_interface/SimpleTransmission</type>
    <joint name="l5_joint_z"/>
    <actuator name="l5_motor_z">
      <hardwareInterface>PositionJointInterface</hardwareInterface>
      <mechanicalReduction>1</mechanicalReduction>
    </actuator>
  </transmission>
  <joint name="l5_joint_y" type="revolute">
    <parent link="l5_z"/>
    <child link="l5_y"/>
    <origin rpy="0 0 0" xyz="0 0 0"/>
    <axis xyz="0 1 0"/>
    <dynamics damping="0.7"/>
    <limit effort="100" lower="-2" upper="2" velocity="10.0"/>
  </joint>
  <transmission name="trans_l5_y">
    <type>transmission_interface/SimpleTransmission</type>
    <joint name="l5_joint_y"/>
    <actuator name="l5_motor_y">
      <hardwareInterface>PositionJointInterface</hardwareInterface>
      <mechanicalReduction>1</mechanicalReduction>
    </actuator>
  </transmission>
  <joint name="l3_joint_x" type="revolute">
    <parent link="l5_y"/>
    <child link="l3_x"/>
    <origin rpy="0 0 0" xyz="0 0.107 0"/>
    <axis xyz="1 0 0"/>
    <dynamics damping="0.7"/>
    <limit effort="100" lower="-2" upper="2" velocity="10.0"/>
  </joint>
  <transmission name="trans_l3_x">
    <type>transmission_interface/SimpleTransmission</type>
    <joint name="l3_joint_x"/>
    <actuator name="l3_motor_x">
      <hardwareInterface>PositionJointInterface</hardwareInterface>
      <mechanicalReduction>1</mechanicalReduction>
    </actuator>
  </transmission>
  <joint name="l3_joint_z" type="revolute">
    <parent link="l3_x"/>
    <child link="l3_z"/>
    <origin rpy="0 0 0" xyz="0 0 0"/>
    <axis xyz="0 0 1"/>
    <dynamics damping="0.7"/>
    <limit effort="100" lower="-2" upper="2" velocity="10.0"/>
  </joint>
  <transmission name="trans_{name}_z">
    <type>transmission_interface/SimpleTransmission</type>
    <joint name="l3_joint_z"/>
    <actuator name="l3_motor_z">
      <hardwareInterface>PositionJointInterface</hardwareInterface>
      <mechanicalReduction>1</mechanicalReduction>
    </actuator>
  </transmission>
  <joint name="l3_joint_y" type="revolute">
    <parent link="l3_z"/>
    <child link="l3_y"/>
    <origin rpy="0 0 0" xyz="0 0 0"/>
    <axis xyz="0 1 0"/>
    <dynamics damping="0.7"/>
    <limit effort="100" lower="-2" upper="2" velocity="10.0"/>
  </joint>
  <transmission name="trans_l3_y">
    <type>transmission_interface/SimpleTransmission</type>
    <joint name="l3_joint_y"/>
    <actuator name="l3_motor_y">
      <hardwareInterface>PositionJointInterface</hardwareInterface>
      <mechanicalReduction>1</mechanicalReduction>
    </actuator>
  </transmission>
  <joint name="t12_joint_x" type="revolute">
    <parent link="l3_y"/>
    <child link="t12_x"/>
    <origin rpy="0 0 0" xyz="0 0.097 0"/>
    <axis xyz="1 0 0"/>
    <dynamics damping="0.7"/>
    <limit effort="100" lower="-2" upper="2" velocity="10.0"/>
  </joint>
  <transmission name="trans_t12_x">
    <type>transmission_interface/SimpleTransmission</type>
    <joint name="t12_joint_x"/>
    <actuator name="t12_motor_x">
      <hardwareInterface>PositionJointInterface</hardwareInterface>
      <mechanicalReduction>1</mechanicalReduction>
    </actuator>
  </transmission>
  <joint name="t12_joint_z" type="revolute">
    <parent link="t12_x"/>
    <child link="t12_z"/>
    <origin rpy="0 0 0" xyz="0 0 0"/>
    <axis xyz="0 0 1"/>
    <dynamics damping="0.7"/>
    <limit effort="100" lower="-2" upper="2" velocity="10.0"/>
  </joint>
  <transmission name="trans_{name}_z">
    <type>transmission_interface/SimpleTransmission</type>
    <joint name="t12_joint_z"/>
    <actuator name="t12_motor_z">
      <hardwareInterface>PositionJointInterface</hardwareInterface>
      <mechanicalReduction>1</mechanicalReduction>
    </actuator>
  </transmission>
  <joint name="t12_joint_y" type="revolute">
    <parent link="t12_z"/>
    <child link="t12_y"/>
    <origin rpy="0 0 0" xyz="0 0 0"/>
    <axis xyz="0 1 0"/>
    <dynamics damping="0.7"/>
    <limit effort="100" lower="-2" upper="2" velocity="10.0"/>
  </joint>
  <transmission name="trans_t12_y">
    <type>transmission_interface/SimpleTransmission</type>
    <joint name="t12_joint_y"/>
    <actuator name="t12_motor_y">
      <hardwareInterface>PositionJointInterface</hardwareInterface>
      <mechanicalReduction>1</mechanicalReduction>
    </actuator>
  </transmission>
  <joint name="t8_joint_x" type="revolute">
    <parent link="t12_y"/>
    <child link="t8_x"/>
    <origin rpy="0 0 0" xyz="0 0.096 0"/>
    <axis xyz="1 0 0"/>
    <dynamics damping="0.7"/>
    <limit effort="100" lower="-2" upper="2" velocity="10.0"/>
  </joint>
  <transmission name="trans_t8_x">
    <type>transmission_interface/SimpleTransmission</type>
    <joint name="t8_joint_x"/>
    <actuator name="t8_motor_x">
      <hardwareInterface>PositionJointInterface</hardwareInterface>
      <mechanicalReduction>1</mechanicalReduction>
    </actuator>
  </transmission>
  <joint name="t8_joint_z" type="revolute">
    <parent link="t8_x"/>
    <child link="t8_z"/>
    <origin rpy="0 0 0" xyz="0 0 0"/>
    <axis xyz="0 0 1"/>
    <dynamics damping="0.7"/>
    <limit effort="100" lower="-2" upper="2" velocity="10.0"/>
  </joint>
  <transmission name="trans_{name}_z">
    <type>transmission_interface/SimpleTransmission</type>
    <joint name="t8_joint_z"/>
    <actuator name="t8_motor_z">
      <hardwareInterface>PositionJointInterface</hardwareInterface>
      <mechanicalReduction>1</mechanicalReduction>
    </actuator>
  </transmission>
  <joint name="t8_joint_y" type="revolute">
    <parent link="t8_z"/>
    <child link="t8_y"/>
    <origin rpy="0 0 0" xyz="0 0 0"/>
    <axis xyz="0 1 0"/>
    <dynamics damping="0.7"/>
    <limit effort="100" lower="-2" upper="2" velocity="10.0"/>
  </joint>
  <transmission name="trans_t8_y">
    <type>transmission_interface/SimpleTransmission</type>
    <joint name="t8_joint_y"/>
    <actuator name="t8_motor_y">
      <hardwareInterface>PositionJointInterface</hardwareInterface>
      <mechanicalReduction>1</mechanicalReduction>
    </actuator>
  </transmission>
  <joint name="neck_joint_x" type="revolute">
    <parent link="t8_y"/>
    <child link="neck_x"/>
    <origin rpy="0 0 0" xyz="0 0.14 0"/>
    <axis xyz="1 0 0"/>
    <dynamics damping="0.7"/>
    <limit effort="100" lower="-2" upper="2" velocity="10.0"/>
  </joint>
  <transmission name="trans_neck_x">
    <type>transmission_interface/SimpleTransmission</type>
    <joint name="neck_joint_x"/>
    <actuator name="neck_motor_x">
      <hardwareInterface>PositionJointInterface</hardwareInterface>
      <mechanicalReduction>1</mechanicalReduction>
    </actuator>
  </transmission>
  <joint name="neck_joint_z" type="revolute">
    <parent link="neck_x"/>
    <child link="neck_z"/>
    <origin rpy="0 0 0" xyz="0 0 0"/>
    <axis xyz="0 0 1"/>
    <dynamics damping="0.7"/>
    <limit effort="100" lower="-2" upper="2" velocity="10.0"/>
  </joint>
  <transmission name="trans_{name}_z">
    <type>transmission_interface/SimpleTransmission</type>
    <joint name="neck_joint_z"/>
    <actuator name="neck_motor_z">
      <hardwareInterface>PositionJointInterface</hardwareInterface>
      <mechanicalReduction>1</mechanicalReduction>
    </actuator>
  </transmission>
  <joint name="neck_joint_y" type="revolute">
    <parent link="neck_z"/>
    <child link="neck_y"/>
    <origin rpy="0 0 0" xyz="0 0 0"/>
    <axis xyz="0 1 0"/>
    <dynamics damping="0.7"/>
    <limit effort="100" lower="-2" upper="2" velocity="10.0"/>
  </joint>
  <transmission name="trans_neck_y">
    <type>transmission_interface/SimpleTransmission</type>
    <joint name="neck_joint_y"/>
    <actuator name="neck_motor_y">
      <hardwareInterface>PositionJointInterface</hardwareInterface>
      <mechanicalReduction>1</mechanicalReduction>
    </actuator>
  </transmission>

  <joint name="head_joint_x" type="revolute">
    <parent link="neck_y"/>
    <child link="head_x"/>
    <origin rpy="0 0 0" xyz="0 0.06 0"/>
    <axis xyz="1 0 0"/>
    <dynamics damping="0.7"/>
    <limit effort="100" lower="-2" upper="2" velocity="10.0"/>
  </joint>
  <transmission name="trans_head_x">
    <type>transmission_interface/SimpleTransmission</type>
    <joint name="head_joint_x"/>
    <actuator name="head_motor_x">
      <hardwareInterface>PositionJointInterface</hardwareInterface>
      <mechanicalReduction>1</mechanicalReduction>
    </actuator>
  </transmission>

  


  <joint name="head_joint_z" type="revolute">
    <parent link="head_x"/>
    <child link="head_z"/>
    <origin rpy="0 0 0" xyz="0 0 0"/>
    <axis xyz="0 0 1"/>
    <dynamics damping="0.7"/>
    <limit effort="100" lower="-2" upper="2" velocity="10.0"/>
  </joint>
  <transmission name="trans_{name}_z">
    <type>transmission_interface/SimpleTransmission</type>
    <joint name="head_joint_z"/>
    <actuator name="head_motor_z">
      <hardwareInterface>PositionJointInterface</hardwareInterface>
      <mechanicalReduction>1</mechanicalReduction>
    </actuator>
  </transmission>
  <joint name="head_joint_y" type="revolute">
    <parent link="head_z"/>
    <child link="head_y"/>
    <origin rpy="0 0 0" xyz="0 0 0"/>
    <axis xyz="0 1 0"/>
    <dynamics damping="0.7"/>
    <limit effort="100" lower="-2" upper="2" velocity="10.0"/>
  </joint>
  <transmission name="trans_head_y">
    <type>transmission_interface/SimpleTransmission</type>
    <joint name="head_joint_y"/>
    <actuator name="head_motor_y">
      <hardwareInterface>PositionJointInterface</hardwareInterface>
      <mechanicalReduction>1</mechanicalReduction>
    </actuator>
  </transmission>



  <link name="right_shoulder_x">
    <inertial>
      <mass value="1"/>
      <origin xyz="0 0 0"/>
      <inertia ixx="1.0" ixy="0.0" ixz="0.0" iyy="1.0" iyz="0.0" izz="1.0"/>
    </inertial>
  </link>
  <link name="right_shoulder_y">
    <inertial>
      <mass value="1"/>
      <origin xyz="0 0 0"/>
      <inertia ixx="1.0" ixy="0.0" ixz="0.0" iyy="1.0" iyz="0.0" izz="1.0"/>
    </inertial>
  </link>
  <link name="right_shoulder_z">
    <inertial>
      <mass value="1"/>
      <origin xyz="0 0 0"/>
      <inertia ixx="1.0" ixy="0.0" ixz="0.0" iyy="1.0" iyz="0.0" izz="1.0"/>
    </inertial>
    <visual>
      <origin rpy="0 0 0" xyz="0 0 0"/>
      <geometry>
        <mesh filename="package://sherpa_spatial_relations/meshes/ShoulderRight.dae"/>
      </geometry>
 <material name="Red"/>
    </visual>
    <collision>
      <origin rpy="0 0 0" xyz="0 0 0"/>
      <geometry>
        <mesh filename="package://sherpa_spatial_relations/meshes/ShoulderRight.dae"/>
      </geometry>
    </collision>
  </link>
  <link name="right_upper_arm_x">
    <inertial>
      <mass value="1"/>
      <origin xyz="0 0 0"/>
      <inertia ixx="1.0" ixy="0.0" ixz="0.0" iyy="1.0" iyz="0.0" izz="1.0"/>
    </inertial>
  </link>
  <link name="right_upper_arm_y">
    <inertial>
      <mass value="1"/>
      <origin xyz="0 0 0"/>
      <inertia ixx="1.0" ixy="0.0" ixz="0.0" iyy="1.0" iyz="0.0" izz="1.0"/>
    </inertial>
  </link>
  <link name="right_upper_arm_z">
    <inertial>
      <mass value="1"/>
      <origin xyz="0 0 0"/>
      <inertia ixx="1.0" ixy="0.0" ixz="0.0" iyy="1.0" iyz="0.0" izz="1.0"/>
    </inertial>
    <visual>
      <origin rpy="0 0 0" xyz="0 0 0"/>
      <geometry>
        <mesh filename="package://sherpa_spatial_relations/meshes/UpperArmRight.dae"/>
      </geometry>
 <material name="Red"/>
    </visual>
    <collision>
      <origin rpy="0 0 0" xyz="0 0 0"/>
      <geometry>
        <mesh filename="package://sherpa_spatial_relations/meshes/UpperArmRight.dae"/>
      </geometry>
    </collision>
  </link>
  <link name="right_lower_arm_x">
    <inertial>
      <mass value="1"/>
      <origin xyz="0 0 0"/>
      <inertia ixx="1.0" ixy="0.0" ixz="0.0" iyy="1.0" iyz="0.0" izz="1.0"/>
    </inertial>
  </link>
  <link name="right_lower_arm_y">
    <inertial>
      <mass value="1"/>
      <origin xyz="0 0 0"/>
      <inertia ixx="1.0" ixy="0.0" ixz="0.0" iyy="1.0" iyz="0.0" izz="1.0"/>
    </inertial>
  </link>
  <link name="right_lower_arm_z">
    <inertial>
      <mass value="1"/>
      <origin xyz="0 0 0"/>
      <inertia ixx="1.0" ixy="0.0" ixz="0.0" iyy="1.0" iyz="0.0" izz="1.0"/>
    </inertial>
    <visual>
      <origin rpy="0 0 0" xyz="0 0 0"/>
      <geometry>
        <mesh filename="package://sherpa_spatial_relations/meshes/LowerArmRight.dae"/>
      </geometry>
<material name="Red"/>
    </visual>
    <collision>
      <origin rpy="0 0 0" xyz="0 0 0"/>
      <geometry>
        <mesh filename="package://sherpa_spatial_relations/meshes/LowerArmRight.dae"/>
      </geometry>
    </collision>
  </link>
  <link name="right_hand_x">
    <inertial>
      <mass value="1"/>
      <origin xyz="0 0 0"/>
      <inertia ixx="1.0" ixy="0.0" ixz="0.0" iyy="1.0" iyz="0.0" izz="1.0"/>
    </inertial>
  </link>
  <link name="right_hand_y">
    <inertial>
      <mass value="1"/>
      <origin xyz="0 0 0"/>
      <inertia ixx="1.0" ixy="0.0" ixz="0.0" iyy="1.0" iyz="0.0" izz="1.0"/>
    </inertial>
  </link>
  <link name="right_hand_z">
    <inertial>
      <mass value="1"/>
      <origin xyz="0 0 0"/>
      <inertia ixx="1.0" ixy="0.0" ixz="0.0" iyy="1.0" iyz="0.0" izz="1.0"/>
    </inertial>
    <visual>
      <origin rpy="0 0 0" xyz="0 0 0"/>
      <geometry>
        <mesh filename="package://sherpa_spatial_relations/meshes/HandRight.dae"/>
      </geometry>
 <material name="Green"/>
    </visual>
    <collision>
      <origin rpy="0 0 0" xyz="0 0 0"/>
      <geometry>
        <mesh filename="package://sherpa_spatial_relations/meshes/HandRight.dae.stl"/>
      </geometry>
    </collision>
  </link>
  <joint name="right_shoulder_joint_x" type="revolute">
    <parent link="neck_y"/>
    <child link="right_shoulder_x"/>
    <origin rpy="0 0 1.57" xyz="-0.03 -0.09 0"/>
    <axis xyz="1 0 0"/>
    <dynamics damping="0.7"/>
    <limit effort="100" lower="-2" upper="2" velocity="10.0"/>
  </joint>
  <transmission name="trans_right_shoulder_x">
    <type>transmission_interface/SimpleTransmission</type>
    <joint name="right_shoulder_joint_x"/>
    <actuator name="right_shoulder_motor_x">
      <hardwareInterface>PositionJointInterface</hardwareInterface>
      <mechanicalReduction>1</mechanicalReduction>
    </actuator>
  </transmission>
  <joint name="right_shoulder_joint_z" type="revolute">
    <parent link="right_shoulder_x"/>
    <child link="right_shoulder_z"/>
    <origin rpy="0 0 0" xyz="0 0 0"/>
    <axis xyz="0 0 1"/>
    <dynamics damping="0.7"/>
    <limit effort="100" lower="-2" upper="2" velocity="10.0"/>
  </joint>
  <transmission name="trans_{name}_z">
    <type>transmission_interface/SimpleTransmission</type>
    <joint name="right_shoulder_joint_z"/>
    <actuator name="right_shoulder_motor_z">
      <hardwareInterface>PositionJointInterface</hardwareInterface>
      <mechanicalReduction>1</mechanicalReduction>
    </actuator>
  </transmission>
  <joint name="right_shoulder_joint_y" type="revolute">
    <parent link="right_shoulder_z"/>
    <child link="right_shoulder_y"/>
    <origin rpy="0 0 0" xyz="0 0 0"/>
    <axis xyz="0 1 0"/>
    <dynamics damping="0.7"/>
    <limit effort="100" lower="-2" upper="2" velocity="10.0"/>
  </joint>
  <transmission name="trans_right_shoulder_y">
    <type>transmission_interface/SimpleTransmission</type>
    <joint name="right_shoulder_joint_y"/>
    <actuator name="right_shoulder_motor_y">
      <hardwareInterface>PositionJointInterface</hardwareInterface>
      <mechanicalReduction>1</mechanicalReduction>
    </actuator>
  </transmission>
  <joint name="right_upper_arm_joint_x" type="revolute">
    <parent link="right_shoulder_y"/>
    <child link="right_upper_arm_x"/>
    <origin rpy="0 0 0" xyz="0 0.14 0"/>
    <axis xyz="1 0 0"/>
    <dynamics damping="0.7"/>
    <limit effort="100" lower="-2" upper="2" velocity="10.0"/>
  </joint>
  <transmission name="trans_right_upper_arm_x">
    <type>transmission_interface/SimpleTransmission</type>
    <joint name="right_upper_arm_joint_x"/>
    <actuator name="right_upper_arm_motor_x">
      <hardwareInterface>PositionJointInterface</hardwareInterface>
      <mechanicalReduction>1</mechanicalReduction>
    </actuator>
  </transmission>
  <joint name="right_upper_arm_joint_z" type="revolute">
    <parent link="right_upper_arm_x"/>
    <child link="right_upper_arm_z"/>
    <origin rpy="0 0 0" xyz="0 0 0"/>
    <axis xyz="0 0 1"/>
    <dynamics damping="0.7"/>
    <limit effort="100" lower="-2" upper="2" velocity="10.0"/>
  </joint>
  <transmission name="trans_{name}_z">
    <type>transmission_interface/SimpleTransmission</type>
    <joint name="right_upper_arm_joint_z"/>
    <actuator name="right_upper_arm_motor_z">
      <hardwareInterface>PositionJointInterface</hardwareInterface>
      <mechanicalReduction>1</mechanicalReduction>
    </actuator>
  </transmission>
  <joint name="right_upper_arm_joint_y" type="revolute">
    <parent link="right_upper_arm_z"/>
    <child link="right_upper_arm_y"/>
    <origin rpy="0 0 0" xyz="0 0 0"/>
    <axis xyz="0 1 0"/>
    <dynamics damping="0.7"/>
    <limit effort="100" lower="-2" upper="2" velocity="10.0"/>
  </joint>
  <transmission name="trans_right_upper_arm_y">
    <type>transmission_interface/SimpleTransmission</type>
    <joint name="right_upper_arm_joint_y"/>
    <actuator name="right_upper_arm_motor_y">
      <hardwareInterface>PositionJointInterface</hardwareInterface>
      <mechanicalReduction>1</mechanicalReduction>
    </actuator>
  </transmission>
  <joint name="right_lower_arm_joint_x" type="revolute">
    <parent link="right_upper_arm_y"/>
    <child link="right_lower_arm_x"/>
    <origin rpy="0 0 0" xyz="0 0.3 0"/>
    <axis xyz="1 0 0"/>
    <dynamics damping="0.7"/>
    <limit effort="100" lower="-2" upper="2" velocity="10.0"/>
  </joint>
  <transmission name="trans_right_lower_arm_x">
    <type>transmission_interface/SimpleTransmission</type>
    <joint name="right_lower_arm_joint_x"/>
    <actuator name="right_lower_arm_motor_x">
      <hardwareInterface>PositionJointInterface</hardwareInterface>
      <mechanicalReduction>1</mechanicalReduction>
    </actuator>
  </transmission>
  <joint name="right_lower_arm_joint_z" type="revolute">
    <parent link="right_lower_arm_x"/>
    <child link="right_lower_arm_z"/>
    <origin rpy="0 0 0" xyz="0 0 0"/>
    <axis xyz="0 0 1"/>
    <dynamics damping="0.7"/>
    <limit effort="100" lower="-2" upper="2" velocity="10.0"/>
  </joint>
  <transmission name="trans_{name}_z">
    <type>transmission_interface/SimpleTransmission</type>
    <joint name="right_lower_arm_joint_z"/>
    <actuator name="right_lower_arm_motor_z">
      <hardwareInterface>PositionJointInterface</hardwareInterface>
      <mechanicalReduction>1</mechanicalReduction>
    </actuator>
  </transmission>
  <joint name="right_lower_arm_joint_y" type="revolute">
    <parent link="right_lower_arm_z"/>
    <child link="right_lower_arm_y"/>
    <origin rpy="0 0 0" xyz="0 0 0"/>
    <axis xyz="0 1 0"/>
    <dynamics damping="0.7"/>
    <limit effort="100" lower="-2" upper="2" velocity="10.0"/>
  </joint>
  <transmission name="trans_right_lower_arm_y">
    <type>transmission_interface/SimpleTransmission</type>
    <joint name="right_lower_arm_joint_y"/>
    <actuator name="right_lower_arm_motor_y">
      <hardwareInterface>PositionJointInterface</hardwareInterface>
      <mechanicalReduction>1</mechanicalReduction>
    </actuator>
  </transmission>
  <joint name="right_hand_joint_x" type="revolute">
    <parent link="right_lower_arm_y"/>
    <child link="right_hand_x"/>
    <origin rpy="0 0 0" xyz="0 0.24 0"/>
    <axis xyz="1 0 0"/>
    <dynamics damping="0.7"/>
    <limit effort="100" lower="-2" upper="2" velocity="10.0"/>
  </joint>
  <transmission name="trans_right_hand_x">
    <type>transmission_interface/SimpleTransmission</type>
    <joint name="right_hand_joint_x"/>
    <actuator name="right_hand_motor_x">
      <hardwareInterface>PositionJointInterface</hardwareInterface>
      <mechanicalReduction>1</mechanicalReduction>
    </actuator>
  </transmission>
  <joint name="right_hand_joint_z" type="revolute">
    <parent link="right_hand_x"/>
    <child link="right_hand_z"/>
    <origin rpy="0 0 0" xyz="0 0 0"/>
    <axis xyz="0 0 1"/>
    <dynamics damping="0.7"/>
    <limit effort="100" lower="-2" upper="2" velocity="10.0"/>
  </joint>
  <transmission name="trans_{name}_z">
    <type>transmission_interface/SimpleTransmission</type>
    <joint name="right_hand_joint_z"/>
    <actuator name="right_hand_motor_z">
      <hardwareInterface>PositionJointInterface</hardwareInterface>
      <mechanicalReduction>1</mechanicalReduction>
    </actuator>
  </transmission>
  <joint name="right_hand_joint_y" type="revolute">
    <parent link="right_hand_z"/>
    <child link="right_hand_y"/>
    <origin rpy="0 0 0" xyz="0 0 0"/>
    <axis xyz="0 1 0"/>
    <dynamics damping="0.7"/>
    <limit effort="100" lower="-2" upper="2" velocity="10.0"/>
  </joint>
  <transmission name="trans_right_hand_y">
    <type>transmission_interface/SimpleTransmission</type>
    <joint name="right_hand_joint_y"/>
    <actuator name="right_hand_motor_y">
      <hardwareInterface>PositionJointInterface</hardwareInterface>
      <mechanicalReduction>1</mechanicalReduction>
    </actuator>
  </transmission>
  <link name="left_shoulder_x">
    <inertial>
      <mass value="1"/>
      <origin xyz="0 0 0"/>
      <inertia ixx="1.0" ixy="0.0" ixz="0.0" iyy="1.0" iyz="0.0" izz="1.0"/>
    </inertial>
  </link>
  <link name="left_shoulder_y">
    <inertial>
      <mass value="1"/>
      <origin xyz="0 0 0"/>
      <inertia ixx="1.0" ixy="0.0" ixz="0.0" iyy="1.0" iyz="0.0" izz="1.0"/>
    </inertial>
  </link>
  <link name="left_shoulder_z">
    <inertial>
      <mass value="1"/>
      <origin xyz="0 0 0"/>
      <inertia ixx="1.0" ixy="0.0" ixz="0.0" iyy="1.0" iyz="0.0" izz="1.0"/>
    </inertial>
    <visual>
      <origin rpy="0 0 0" xyz="0 0 0"/>
      <geometry>
        <mesh filename="package://sherpa_spatial_relations/meshes/ShoulderLeft.dae"/>
      </geometry>
      <material name="Red"/>
    </visual>
    <collision>
      <origin rpy="0 0 0" xyz="0 0 0"/>
      <geometry>
        <mesh filename="package://sherpa_spatial_relations/meshes/ShoulderLeft.dae.stl"/>
      </geometry>
    </collision>
  </link>
  <link name="left_upper_arm_x">
    <inertial>
      <mass value="1"/>
      <origin xyz="0 0 0"/>
      <inertia ixx="1.0" ixy="0.0" ixz="0.0" iyy="1.0" iyz="0.0" izz="1.0"/>
    </inertial>
  </link>
  <link name="left_upper_arm_y">
    <inertial>
      <mass value="1"/>
      <origin xyz="0 0 0"/>
      <inertia ixx="1.0" ixy="0.0" ixz="0.0" iyy="1.0" iyz="0.0" izz="1.0"/>
    </inertial>
  </link>
  <link name="left_upper_arm_z">
    <inertial>
      <mass value="1"/>
      <origin xyz="0 0 0"/>
      <inertia ixx="1.0" ixy="0.0" ixz="0.0" iyy="1.0" iyz="0.0" izz="1.0"/>
    </inertial>
    <visual>
      <origin rpy="0 0 0" xyz="0 0 0"/>
      <geometry>
        <mesh filename="package://sherpa_spatial_relations/meshes/UpperArmLeft.dae"/>
      </geometry>
 <material name="Red"/>
    </visual>
    <collision>
      <origin rpy="0 0 0" xyz="0 0 0"/>
      <geometry>
        <mesh filename="package://sherpa_spatial_relations/meshes/UpperArmLeft.dae.stl"/>
      </geometry>
    </collision>
  </link>
  <link name="left_lower_arm_x">
    <inertial>
      <mass value="1"/>
      <origin xyz="0 0 0"/>
      <inertia ixx="1.0" ixy="0.0" ixz="0.0" iyy="1.0" iyz="0.0" izz="1.0"/>
    </inertial>
  </link>
  <link name="left_lower_arm_y">
    <inertial>
      <mass value="1"/>
      <origin xyz="0 0 0"/>
      <inertia ixx="1.0" ixy="0.0" ixz="0.0" iyy="1.0" iyz="0.0" izz="1.0"/>
    </inertial>
  </link>
  <link name="left_lower_arm_z">
    <inertial>
      <mass value="1"/>
      <origin xyz="0 0 0"/>
      <inertia ixx="1.0" ixy="0.0" ixz="0.0" iyy="1.0" iyz="0.0" izz="1.0"/>
    </inertial>
    <visual>
      <origin rpy="0 0 0" xyz="0 0 0"/>
      <geometry>
        <mesh filename="package://sherpa_spatial_relations/meshes/LowerArmLeft.dae"/>
      </geometry>
 <material name="Red"/>
    </visual>
    <collision>
      <origin rpy="0 0 0" xyz="0 0 0"/>
      <geometry>
        <mesh filename="package://sherpa_spatial_relations/meshes/LowerArmLeft.dae.stl" />
      </geometry>
    </collision>
  </link>
  <link name="left_hand_x">
    <inertial>
      <mass value="1"/>
      <origin xyz="0 0 0"/>
      <inertia ixx="1.0" ixy="0.0" ixz="0.0" iyy="1.0" iyz="0.0" izz="1.0"/>
    </inertial>
  </link>
  <link name="left_hand_y">
    <inertial>
      <mass value="1"/>
      <origin xyz="0 0 0"/>
      <inertia ixx="1.0" ixy="0.0" ixz="0.0" iyy="1.0" iyz="0.0" izz="1.0"/>
    </inertial>
  </link>
  <link name="left_hand_z">
    <inertial>
      <mass value="1"/>
      <origin xyz="0 0 0"/>
      <inertia ixx="1.0" ixy="0.0" ixz="0.0" iyy="1.0" iyz="0.0" izz="1.0"/>
    </inertial>
    <visual>
      <origin rpy="0 0 0" xyz="0 0 0"/>
      <geometry>
        <mesh filename="package://sherpa_spatial_relations/meshes/HandLeft.dae"/>
      </geometry>
 <material name="Green"/>
    </visual>
    <collision>
      <origin rpy="0 0 0" xyz="0 0 0"/>
      <geometry>
        <mesh filename="package://sherpa_spatial_relations/meshes/HandLeft.dae.stl"/>
      </geometry>
    </collision>
  </link>
  <joint name="left_shoulder_joint_x" type="revolute">
    <parent link="neck_y"/>
    <child link="left_shoulder_x"/>
    <origin rpy="0 0 -1.57" xyz="0.03 -0.09 0"/>
    <axis xyz="1 0 0"/>
    <dynamics damping="0.7"/>
    <limit effort="100" lower="-2" upper="2" velocity="10.0"/>
  </joint>
  <transmission name="trans_left_shoulder_x">
    <type>transmission_interface/SimpleTransmission</type>
    <joint name="left_shoulder_joint_x"/>
    <actuator name="left_shoulder_motor_x">
      <hardwareInterface>PositionJointInterface</hardwareInterface>
      <mechanicalReduction>1</mechanicalReduction>
    </actuator>
  </transmission>
  <joint name="left_shoulder_joint_z" type="revolute">
    <parent link="left_shoulder_x"/>
    <child link="left_shoulder_z"/>
    <origin rpy="0 0 0" xyz="0 0 0"/>
    <axis xyz="0 0 1"/>
    <dynamics damping="0.7"/>
    <limit effort="100" lower="-2" upper="2" velocity="10.0"/>
  </joint>
  <transmission name="trans_{name}_z">
    <type>transmission_interface/SimpleTransmission</type>
    <joint name="left_shoulder_joint_z"/>
    <actuator name="left_shoulder_motor_z">
      <hardwareInterface>PositionJointInterface</hardwareInterface>
      <mechanicalReduction>1</mechanicalReduction>
    </actuator>
  </transmission>
  <joint name="left_shoulder_joint_y" type="revolute">
    <parent link="left_shoulder_z"/>
    <child link="left_shoulder_y"/>
    <origin rpy="0 0 0" xyz="0 0 0"/>
    <axis xyz="0 1 0"/>
    <dynamics damping="0.7"/>
    <limit effort="100" lower="-2" upper="2" velocity="10.0"/>
  </joint>
  <transmission name="trans_left_shoulder_y">
    <type>transmission_interface/SimpleTransmission</type>
    <joint name="left_shoulder_joint_y"/>
    <actuator name="left_shoulder_motor_y">
      <hardwareInterface>PositionJointInterface</hardwareInterface>
      <mechanicalReduction>1</mechanicalReduction>
    </actuator>
  </transmission>
  <joint name="left_upper_arm_joint_x" type="revolute">
    <parent link="left_shoulder_y"/>
    <child link="left_upper_arm_x"/>
    <origin rpy="0 0 0" xyz="0 0.14 0"/>
    <axis xyz="1 0 0"/>
    <dynamics damping="0.7"/>
    <limit effort="100" lower="-2" upper="2" velocity="10.0"/>
  </joint>
  <transmission name="trans_left_upper_arm_x">
    <type>transmission_interface/SimpleTransmission</type>
    <joint name="left_upper_arm_joint_x"/>
    <actuator name="left_upper_arm_motor_x">
      <hardwareInterface>PositionJointInterface</hardwareInterface>
      <mechanicalReduction>1</mechanicalReduction>
    </actuator>
  </transmission>
  <joint name="left_upper_arm_joint_z" type="revolute">
    <parent link="left_upper_arm_x"/>
    <child link="left_upper_arm_z"/>
    <origin rpy="0 0 0" xyz="0 0 0"/>
    <axis xyz="0 0 1"/>
    <dynamics damping="0.7"/>
    <limit effort="100" lower="-2" upper="2" velocity="10.0"/>
  </joint>
  <transmission name="trans_{name}_z">
    <type>transmission_interface/SimpleTransmission</type>
    <joint name="left_upper_arm_joint_z"/>
    <actuator name="left_upper_arm_motor_z">
      <hardwareInterface>PositionJointInterface</hardwareInterface>
      <mechanicalReduction>1</mechanicalReduction>
    </actuator>
  </transmission>
  <joint name="left_upper_arm_joint_y" type="revolute">
    <parent link="left_upper_arm_z"/>
    <child link="left_upper_arm_y"/>
    <origin rpy="0 0 0" xyz="0 0 0"/>
    <axis xyz="0 1 0"/>
    <dynamics damping="0.7"/>
    <limit effort="100" lower="-2" upper="2" velocity="10.0"/>
  </joint>
  <transmission name="trans_left_upper_arm_y">
    <type>transmission_interface/SimpleTransmission</type>
    <joint name="left_upper_arm_joint_y"/>
    <actuator name="left_upper_arm_motor_y">
      <hardwareInterface>PositionJointInterface</hardwareInterface>
      <mechanicalReduction>1</mechanicalReduction>
    </actuator>
  </transmission>
  <joint name="left_lower_arm_joint_x" type="revolute">
    <parent link="left_upper_arm_y"/>
    <child link="left_lower_arm_x"/>
    <origin rpy="0 0 0" xyz="0 0.3 0"/>
    <axis xyz="1 0 0"/>
    <dynamics damping="0.7"/>
    <limit effort="100" lower="-2" upper="2" velocity="10.0"/>
  </joint>
  <transmission name="trans_left_lower_arm_x">
    <type>transmission_interface/SimpleTransmission</type>
    <joint name="left_lower_arm_joint_x"/>
    <actuator name="left_lower_arm_motor_x">
      <hardwareInterface>PositionJointInterface</hardwareInterface>
      <mechanicalReduction>1</mechanicalReduction>
    </actuator>
  </transmission>
  <joint name="left_lower_arm_joint_z" type="revolute">
    <parent link="left_lower_arm_x"/>
    <child link="left_lower_arm_z"/>
    <origin rpy="0 0 0" xyz="0 0 0"/>
    <axis xyz="0 0 1"/>
    <dynamics damping="0.7"/>
    <limit effort="100" lower="-2" upper="2" velocity="10.0"/>
  </joint>
  <transmission name="trans_{name}_z">
    <type>transmission_interface/SimpleTransmission</type>
    <joint name="left_lower_arm_joint_z"/>
    <actuator name="left_lower_arm_motor_z">
      <hardwareInterface>PositionJointInterface</hardwareInterface>
      <mechanicalReduction>1</mechanicalReduction>
    </actuator>
  </transmission>
  <joint name="left_lower_arm_joint_y" type="revolute">
    <parent link="left_lower_arm_z"/>
    <child link="left_lower_arm_y"/>
    <origin rpy="0 0 0" xyz="0 0 0"/>
    <axis xyz="0 1 0"/>
    <dynamics damping="0.7"/>
    <limit effort="100" lower="-2" upper="2" velocity="10.0"/>
  </joint>
  <transmission name="trans_left_lower_arm_y">
    <type>transmission_interface/SimpleTransmission</type>
    <joint name="left_lower_arm_joint_y"/>
    <actuator name="left_lower_arm_motor_y">
      <hardwareInterface>PositionJointInterface</hardwareInterface>
      <mechanicalReduction>1</mechanicalReduction>
    </actuator>
  </transmission>
  <joint name="left_hand_joint_x" type="revolute">
    <parent link="left_lower_arm_y"/>
    <child link="left_hand_x"/>
    <origin rpy="0 0 0" xyz="0 0.24 0"/>
    <axis xyz="1 0 0"/>
    <dynamics damping="0.7"/>
    <limit effort="100" lower="-2" upper="2" velocity="10.0"/>
  </joint>
  <transmission name="trans_left_hand_x">
    <type>transmission_interface/SimpleTransmission</type>
    <joint name="left_hand_joint_x"/>
    <actuator name="left_hand_motor_x">
      <hardwareInterface>PositionJointInterface</hardwareInterface>
      <mechanicalReduction>1</mechanicalReduction>
    </actuator>
  </transmission>
  <joint name="left_hand_joint_z" type="revolute">
    <parent link="left_hand_x"/>
    <child link="left_hand_z"/>
    <origin rpy="0 0 0" xyz="0 0 0"/>
    <axis xyz="0 0 1"/>
    <dynamics damping="0.7"/>
    <limit effort="100" lower="-2" upper="2" velocity="10.0"/>
  </joint>
  <transmission name="trans_{name}_z">
    <type>transmission_interface/SimpleTransmission</type>
    <joint name="left_hand_joint_z"/>
    <actuator name="left_hand_motor_z">
      <hardwareInterface>PositionJointInterface</hardwareInterface>
      <mechanicalReduction>1</mechanicalReduction>
    </actuator>
  </transmission>
  <joint name="left_hand_joint_y" type="revolute">
    <parent link="left_hand_z"/>
    <child link="left_hand_y"/>
    <origin rpy="0 0 0" xyz="0 0 0"/>
    <axis xyz="0 1 0"/>
    <dynamics damping="0.7"/>
    <limit effort="100" lower="-2" upper="2" velocity="10.0"/>
  </joint>
  <transmission name="trans_left_hand_y">
    <type>transmission_interface/SimpleTransmission</type>
    <joint name="left_hand_joint_y"/>
    <actuator name="left_hand_motor_y">
      <hardwareInterface>PositionJointInterface</hardwareInterface>
      <mechanicalReduction>1</mechanicalReduction>
    </actuator>
  </transmission>
  <link name="right_upper_leg_x">
    <inertial>
      <mass value="1"/>
      <origin xyz="0 0 0"/>
      <inertia ixx="1.0" ixy="0.0" ixz="0.0" iyy="1.0" iyz="0.0" izz="1.0"/>
    </inertial>
  </link>
  <link name="right_upper_leg_y">
    <inertial>
      <mass value="1"/>
      <origin xyz="0 0 0"/>
      <inertia ixx="1.0" ixy="0.0" ixz="0.0" iyy="1.0" iyz="0.0" izz="1.0"/>
    </inertial>
  </link>
  <link name="right_upper_leg_z">
    <inertial>
      <mass value="1"/>
      <origin xyz="0 0 0"/>
      <inertia ixx="1.0" ixy="0.0" ixz="0.0" iyy="1.0" iyz="0.0" izz="1.0"/>
    </inertial>
    <visual>
      <origin rpy="0 0 0" xyz="0 0 0"/>
      <geometry>
        <mesh filename="package://sherpa_spatial_relations/meshes/UpperLegRight.dae" />
      </geometry> 
<material name="Blue"/>
    </visual>
    <collision>
      <origin rpy="0 0 0" xyz="0 0 0"/>
      <geometry>
        <mesh filename="package://sherpa_spatial_relations/meshes/UpperLegRight.dae.stl"/>
      </geometry>
    </collision>
  </link>
  <link name="right_lower_leg_x">
    <inertial>
      <mass value="1"/>
      <origin xyz="0 0 0"/>
      <inertia ixx="1.0" ixy="0.0" ixz="0.0" iyy="1.0" iyz="0.0" izz="1.0"/>
    </inertial>
  </link>
  <link name="right_lower_leg_y">
    <inertial>
      <mass value="1"/>
      <origin xyz="0 0 0"/>
      <inertia ixx="1.0" ixy="0.0" ixz="0.0" iyy="1.0" iyz="0.0" izz="1.0"/>
    </inertial>
  </link>
  <link name="right_lower_leg_z">
    <inertial>
      <mass value="1"/>
      <origin xyz="0 0 0"/>
      <inertia ixx="1.0" ixy="0.0" ixz="0.0" iyy="1.0" iyz="0.0" izz="1.0"/>
    </inertial>
    <visual>
      <origin rpy="0 0 0" xyz="0 0 0"/>
      <geometry>
        <mesh filename="package://sherpa_spatial_relations/meshes/LowerLegRight.dae" />
      </geometry>
 <material name="Blue"/>
    </visual>
    <collision>
      <origin rpy="0 0 0" xyz="0 0 0"/>
      <geometry>
        <mesh filename="package://sherpa_spatial_relations/meshes/LowerLegRight.dae.stl" />
      </geometry>
    </collision>
  </link>
  <link name="left_foot_x">
    <inertial>
      <mass value="1"/>
      <origin xyz="0 0 0"/>
      <inertia ixx="1.0" ixy="0.0" ixz="0.0" iyy="1.0" iyz="0.0" izz="1.0"/>
    </inertial>
  </link>
  <link name="left_foot_y">
    <inertial>
      <mass value="1"/>
      <origin xyz="0 0 0"/>
      <inertia ixx="1.0" ixy="0.0" ixz="0.0" iyy="1.0" iyz="0.0" izz="1.0"/>
    </inertial>
  </link>
  <link name="left_foot_z">
    <inertial>
      <mass value="1"/>
      <origin xyz="0 0 0"/>
      <inertia ixx="1.0" ixy="0.0" ixz="0.0" iyy="1.0" iyz="0.0" izz="1.0"/>
    </inertial>
    <visual>
      <origin rpy="0 0 0" xyz="0 0 0"/>
      <geometry>
        <mesh filename="package://sherpa_spatial_relations/meshes/FootLeft.dae" />
      </geometry>
<material name="Black"/>
    </visual>
    <collision>
      <origin rpy="0 0 0" xyz="0 0 0"/>
      <geometry>
        <mesh filename="package://sherpa_spatial_relations/meshes/FootLeft.dae.stl"/>
      </geometry>
    </collision>
  </link>
  <link name="left_toe_x">
    <inertial>
      <mass value="1"/>
      <origin xyz="0 0 0"/>
      <inertia ixx="1.0" ixy="0.0" ixz="0.0" iyy="1.0" iyz="0.0" izz="1.0"/>
    </inertial>
  </link>
  <link name="left_toe_y">
    <inertial>
      <mass value="1"/>
      <origin xyz="0 0 0"/>
      <inertia ixx="1.0" ixy="0.0" ixz="0.0" iyy="1.0" iyz="0.0" izz="1.0"/>
    </inertial>
  </link>
  <link name="left_toe_z">
    <inertial>
      <mass value="1"/>
      <origin xyz="0 0 0"/>
      <inertia ixx="1.0" ixy="0.0" ixz="0.0" iyy="1.0" iyz="0.0" izz="1.0"/>
    </inertial>
    <visual>
      <origin rpy="0 0 0" xyz="0 0 0"/>
      <geometry>
        <mesh filename="package://sherpa_spatial_relations/meshes/ToeLeft.dae" />
      </geometry>
 <material name="Black"/>
    </visual>
    <collision>
      <origin rpy="0 0 0" xyz="0 0 0"/>
      <geometry>
        <mesh filename="package://sherpa_spatial_relations/meshes/ToeLeft.dae.stl" />
      </geometry>
    </collision>
  </link>
  <link name="right_foot_x">
    <inertial>
      <mass value="1"/>
      <origin xyz="0 0 0"/>
      <inertia ixx="1.0" ixy="0.0" ixz="0.0" iyy="1.0" iyz="0.0" izz="1.0"/>
    </inertial>
  </link>
  <link name="right_foot_y">
    <inertial>
      <mass value="1"/>
      <origin xyz="0 0 0"/>
      <inertia ixx="1.0" ixy="0.0" ixz="0.0" iyy="1.0" iyz="0.0" izz="1.0"/>
    </inertial>
  </link>
  <link name="right_foot_z">
    <inertial>
      <mass value="1"/>
      <origin xyz="0 0 0"/>
      <inertia ixx="1.0" ixy="0.0" ixz="0.0" iyy="1.0" iyz="0.0" izz="1.0"/>
    </inertial>
    <visual>
      <origin rpy="0 0 0" xyz="0 0 0"/>
      <geometry>
        <mesh filename="package://sherpa_spatial_relations/meshes/FootRight.dae"/>
      </geometry>
  <material name="Black"/>
    </visual>
    <collision>
      <origin rpy="0 0 0" xyz="0 0 0"/>
      <geometry>
        <mesh filename="package://sherpa_spatial_relations/meshes/FootRight.dae.stl"/>
      </geometry>
    </collision>
  </link>
  <link name="right_toe_x">
    <inertial>
      <mass value="1"/>
      <origin xyz="0 0 0"/>
      <inertia ixx="1.0" ixy="0.0" ixz="0.0" iyy="1.0" iyz="0.0" izz="1.0"/>
    </inertial>
  </link>
  <link name="right_toe_y">
    <inertial>
      <mass value="1"/>
      <origin xyz="0 0 0"/>
      <inertia ixx="1.0" ixy="0.0" ixz="0.0" iyy="1.0" iyz="0.0" izz="1.0"/>
    </inertial>
  </link>
  <link name="right_toe_z">
    <inertial>
      <mass value="1"/>
      <origin xyz="0 0 0"/>
      <inertia ixx="1.0" ixy="0.0" ixz="0.0" iyy="1.0" iyz="0.0" izz="1.0"/>
    </inertial>
    <visual>
      <origin rpy="0 0 0" xyz="0 0 0"/>
      <geometry>
        <mesh filename="package://sherpa_spatial_relations/meshes/ToeRight.dae"/>
      </geometry>
<material name="Black"/>
    </visual>
    <collision>
      <origin rpy="0 0 0" xyz="0 0 0"/>
      <geometry>
        <mesh filename="package://sherpa_spatial_relations/meshes/ToeRight.dae.stl" />
      </geometry>
    </collision>
  </link>
  <joint name="right_upper_leg_joint_x" type="revolute">
    <parent link="pelvis_y"/>
    <child link="right_upper_leg_x"/>
    <origin rpy="3.14 0 0" xyz="-0.079 0 0"/>
    <axis xyz="1 0 0"/>
    <dynamics damping="0.7"/>
    <limit effort="100" lower="-2" upper="2" velocity="10.0"/>
  </joint>
  <transmission name="trans_right_upper_leg_x">
    <type>transmission_interface/SimpleTransmission</type>
    <joint name="right_upper_leg_joint_x"/>
    <actuator name="right_upper_leg_motor_x">
      <hardwareInterface>PositionJointInterface</hardwareInterface>
      <mechanicalReduction>1</mechanicalReduction>
    </actuator>
  </transmission>
  <joint name="right_upper_leg_joint_z" type="revolute">
    <parent link="right_upper_leg_x"/>
    <child link="right_upper_leg_z"/>
    <origin rpy="0 0 0" xyz="0 0 0"/>
    <axis xyz="0 0 1"/>
    <dynamics damping="0.7"/>
    <limit effort="100" lower="-2" upper="2" velocity="10.0"/>
  </joint>
  <transmission name="trans_{name}_z">
    <type>transmission_interface/SimpleTransmission</type>
    <joint name="right_upper_leg_joint_z"/>
    <actuator name="right_upper_leg_motor_z">
      <hardwareInterface>PositionJointInterface</hardwareInterface>
      <mechanicalReduction>1</mechanicalReduction>
    </actuator>
  </transmission>
  <joint name="right_upper_leg_joint_y" type="revolute">
    <parent link="right_upper_leg_z"/>
    <child link="right_upper_leg_y"/>
    <origin rpy="0 0 0" xyz="0 0 0"/>
    <axis xyz="0 1 0"/>
    <dynamics damping="0.7"/>
    <limit effort="100" lower="-2" upper="2" velocity="10.0"/>
  </joint>
  <transmission name="trans_right_upper_leg_y">
    <type>transmission_interface/SimpleTransmission</type>
    <joint name="right_upper_leg_joint_y"/>
    <actuator name="right_upper_leg_motor_y">
      <hardwareInterface>PositionJointInterface</hardwareInterface>
      <mechanicalReduction>1</mechanicalReduction>
    </actuator>
  </transmission>
  <joint name="right_lower_leg_joint_x" type="revolute">
    <parent link="right_upper_leg_y"/>
    <child link="right_lower_leg_x"/>
    <origin rpy="0 0 0" xyz="0 0.41 0"/>
    <axis xyz="1 0 0"/>
    <dynamics damping="0.7"/>
    <limit effort="100" lower="-2" upper="2" velocity="10.0"/>
  </joint>
  <transmission name="trans_right_lower_leg_x">
    <type>transmission_interface/SimpleTransmission</type>
    <joint name="right_lower_leg_joint_x"/>
    <actuator name="right_lower_leg_motor_x">
      <hardwareInterface>PositionJointInterface</hardwareInterface>
      <mechanicalReduction>1</mechanicalReduction>
    </actuator>
  </transmission>
  <joint name="right_lower_leg_joint_z" type="revolute">
    <parent link="right_lower_leg_x"/>
    <child link="right_lower_leg_z"/>
    <origin rpy="0 0 0" xyz="0 0 0"/>
    <axis xyz="0 0 1"/>
    <dynamics damping="0.7"/>
    <limit effort="100" lower="-2" upper="2" velocity="10.0"/>
  </joint>
  <transmission name="trans_{name}_z">
    <type>transmission_interface/SimpleTransmission</type>
    <joint name="right_lower_leg_joint_z"/>
    <actuator name="right_lower_leg_motor_z">
      <hardwareInterface>PositionJointInterface</hardwareInterface>
      <mechanicalReduction>1</mechanicalReduction>
    </actuator>
  </transmission>
  <joint name="right_lower_leg_joint_y" type="revolute">
    <parent link="right_lower_leg_z"/>
    <child link="right_lower_leg_y"/>
    <origin rpy="0 0 0" xyz="0 0 0"/>
    <axis xyz="0 1 0"/>
    <dynamics damping="0.7"/>
    <limit effort="100" lower="-2" upper="2" velocity="10.0"/>
  </joint>
  <transmission name="trans_right_lower_leg_y">
    <type>transmission_interface/SimpleTransmission</type>
    <joint name="right_lower_leg_joint_y"/>
    <actuator name="right_lower_leg_motor_y">
      <hardwareInterface>PositionJointInterface</hardwareInterface>
      <mechanicalReduction>1</mechanicalReduction>
    </actuator>
  </transmission>
  <joint name="right_foot_joint_x" type="revolute">
    <parent link="right_lower_leg_y"/>
    <child link="right_foot_x"/>
    <origin rpy="-1.15 0 0" xyz="0. 0.4 0"/>
    <axis xyz="1 0 0"/>
    <dynamics damping="0.7"/>
    <limit effort="100" lower="-2" upper="2" velocity="10.0"/>
  </joint>
  <transmission name="trans_right_foot_x">
    <type>transmission_interface/SimpleTransmission</type>
    <joint name="right_foot_joint_x"/>
    <actuator name="right_foot_motor_x">
      <hardwareInterface>PositionJointInterface</hardwareInterface>
      <mechanicalReduction>1</mechanicalReduction>
    </actuator>
  </transmission>
  <joint name="right_foot_joint_z" type="revolute">
    <parent link="right_foot_x"/>
    <child link="right_foot_z"/>
    <origin rpy="0 0 0" xyz="0 0 0"/>
    <axis xyz="0 0 1"/>
    <dynamics damping="0.7"/>
    <limit effort="100" lower="-2" upper="2" velocity="10.0"/>
  </joint>
  <transmission name="trans_{name}_z">
    <type>transmission_interface/SimpleTransmission</type>
    <joint name="right_foot_joint_z"/>
    <actuator name="right_foot_motor_z">
      <hardwareInterface>PositionJointInterface</hardwareInterface>
      <mechanicalReduction>1</mechanicalReduction>
    </actuator>
  </transmission>
  <joint name="right_foot_joint_y" type="revolute">
    <parent link="right_foot_z"/>
    <child link="right_foot_y"/>
    <origin rpy="0 0 0" xyz="0 0 0"/>
    <axis xyz="0 1 0"/>
    <dynamics damping="0.7"/>
    <limit effort="100" lower="-2" upper="2" velocity="10.0"/>
  </joint>
  <transmission name="trans_right_foot_y">
    <type>transmission_interface/SimpleTransmission</type>
    <joint name="right_foot_joint_y"/>
    <actuator name="right_foot_motor_y">
      <hardwareInterface>PositionJointInterface</hardwareInterface>
      <mechanicalReduction>1</mechanicalReduction>
    </actuator>
  </transmission>
  <joint name="right_toe_joint_x" type="revolute">
    <parent link="right_foot_y"/>
    <child link="right_toe_x"/>
    <origin rpy="0 0 0" xyz="0 0.18 0"/>
    <axis xyz="1 0 0"/>
    <dynamics damping="0.7"/>
    <limit effort="100" lower="-2" upper="2" velocity="10.0"/>
  </joint>
  <transmission name="trans_right_toe_x">
    <type>transmission_interface/SimpleTransmission</type>
    <joint name="right_toe_joint_x"/>
    <actuator name="right_toe_motor_x">
      <hardwareInterface>PositionJointInterface</hardwareInterface>
      <mechanicalReduction>1</mechanicalReduction>
    </actuator>
  </transmission>
  <joint name="right_toe_joint_z" type="revolute">
    <parent link="right_toe_x"/>
    <child link="right_toe_z"/>
    <origin rpy="0 0 0" xyz="0 0 0"/>
    <axis xyz="0 0 1"/>
    <dynamics damping="0.7"/>
    <limit effort="100" lower="-2" upper="2" velocity="10.0"/>
  </joint>
  <transmission name="trans_{name}_z">
    <type>transmission_interface/SimpleTransmission</type>
    <joint name="right_toe_joint_z"/>
    <actuator name="right_toe_motor_z">
      <hardwareInterface>PositionJointInterface</hardwareInterface>
      <mechanicalReduction>1</mechanicalReduction>
    </actuator>
  </transmission>
  <joint name="right_toe_joint_y" type="revolute">
    <parent link="right_toe_z"/>
    <child link="right_toe_y"/>
    <origin rpy="0 0 0" xyz="0 0 0"/>
    <axis xyz="0 1 0"/>
    <dynamics damping="0.7"/>
    <limit effort="100" lower="-2" upper="2" velocity="10.0"/>
  </joint>
  <transmission name="trans_right_toe_y">
    <type>transmission_interface/SimpleTransmission</type>
    <joint name="right_toe_joint_y"/>
    <actuator name="right_toe_motor_y">
      <hardwareInterface>PositionJointInterface</hardwareInterface>
      <mechanicalReduction>1</mechanicalReduction>
    </actuator>
  </transmission>
  <link name="left_upper_leg_x">
    <inertial>
      <mass value="1"/>
      <origin xyz="0 0 0"/>
      <inertia ixx="1.0" ixy="0.0" ixz="0.0" iyy="1.0" iyz="0.0" izz="1.0"/>
    </inertial>
  </link>
  <link name="left_upper_leg_y">
    <inertial>
      <mass value="1"/>
      <origin xyz="0 0 0"/>
      <inertia ixx="1.0" ixy="0.0" ixz="0.0" iyy="1.0" iyz="0.0" izz="1.0"/>
    </inertial>
  </link>
  <link name="left_upper_leg_z">
    <inertial>
      <mass value="1"/>
      <origin xyz="0 0 0"/>
      <inertia ixx="1.0" ixy="0.0" ixz="0.0" iyy="1.0" iyz="0.0" izz="1.0"/>
    </inertial>
    <visual>
      <origin rpy="0 0 0" xyz="0 0 0"/>
      <geometry>
        <mesh filename="package://sherpa_spatial_relations/meshes/UpperLegLeft.dae"/>
      </geometry>
 <material name="Blue"/>
    </visual>
    <collision>
      <origin rpy="0 0 0" xyz="0 0 0"/>
      <geometry>
        <mesh filename="package://sherpa_spatial_relations/meshes/UpperLegLeft.dae.stl" />
      </geometry>
    </collision>
  </link>
  <link name="left_lower_leg_x">
    <inertial>
      <mass value="1"/>
      <origin xyz="0 0 0"/>
      <inertia ixx="1.0" ixy="0.0" ixz="0.0" iyy="1.0" iyz="0.0" izz="1.0"/>
    </inertial>
  </link>
  <link name="left_lower_leg_y">
    <inertial>
      <mass value="1"/>
      <origin xyz="0 0 0"/>
      <inertia ixx="1.0" ixy="0.0" ixz="0.0" iyy="1.0" iyz="0.0" izz="1.0"/>
    </inertial>
  </link>
  <link name="left_lower_leg_z">
    <inertial>
      <mass value="1"/>
      <origin xyz="0 0 0"/>
      <inertia ixx="1.0" ixy="0.0" ixz="0.0" iyy="1.0" iyz="0.0" izz="1.0"/>
    </inertial>
    <visual>
      <origin rpy="0 0 0" xyz="0 0 0"/>
      <geometry>
        <mesh filename="package://sherpa_spatial_relations/meshes/LowerLegLeft.dae"/>
      </geometry>
 <material name="Blue"/>
    </visual>
    <collision>
      <origin rpy="0 0 0" xyz="0 0 0"/>
      <geometry>
        <mesh filename="package://sherpa_spatial_relations/meshes/LowerLegLeft.dae.stl"/>
      </geometry>
    </collision>
  </link>
  <link name="left_foot_x">
    <inertial>
      <mass value="1"/>
      <origin xyz="0 0 0"/>
      <inertia ixx="1.0" ixy="0.0" ixz="0.0" iyy="1.0" iyz="0.0" izz="1.0"/>
    </inertial>
  </link>
  <link name="left_foot_y">
    <inertial>
      <mass value="1"/>
      <origin xyz="0 0 0"/>
      <inertia ixx="1.0" ixy="0.0" ixz="0.0" iyy="1.0" iyz="0.0" izz="1.0"/>
    </inertial>
  </link>
  <link name="left_foot_z">
    <inertial>
      <mass value="1"/>
      <origin xyz="0 0 0"/>
      <inertia ixx="1.0" ixy="0.0" ixz="0.0" iyy="1.0" iyz="0.0" izz="1.0"/>
    </inertial>
    <visual>
      <origin rpy="0 0 0" xyz="0 0 0"/>
      <geometry>
        <mesh filename="package://sherpa_spatial_relations/meshes/FootLeft.dae"/>
      </geometry>
     <material name="Black"/>
    </visual>
    <collision>
      <origin rpy="0 0 0" xyz="0 0 0"/>
      <geometry>
        <mesh filename="package://sherpa_spatial_relations/meshes/FootLeft.dae.stl"/>
      </geometry>
    </collision>
  </link>
  <link name="left_toe_x">
    <inertial>
      <mass value="1"/>
      <origin xyz="0 0 0"/>
      <inertia ixx="1.0" ixy="0.0" ixz="0.0" iyy="1.0" iyz="0.0" izz="1.0"/>
    </inertial>
  </link>
  <link name="left_toe_y">
    <inertial>
      <mass value="1"/>
      <origin xyz="0 0 0"/>
      <inertia ixx="1.0" ixy="0.0" ixz="0.0" iyy="1.0" iyz="0.0" izz="1.0"/>
    </inertial>
  </link>
  <link name="left_toe_z">
    <inertial>
      <mass value="1"/>
      <origin xyz="0 0 0"/>
      <inertia ixx="1.0" ixy="0.0" ixz="0.0" iyy="1.0" iyz="0.0" izz="1.0"/>
    </inertial>
    <visual>
      <origin rpy="0 0 0" xyz="0 0 0"/>
      <geometry>
        <mesh filename="package://sherpa_genius_description/meshes/ToeLeft.dae"/>
      </geometry>
 <material name="Black"/>
    </visual>
    <collision>
      <origin rpy="0 0 0" xyz="0 0 0"/>
      <geometry>
        <mesh filename="package://sherpa_genius_description/meshes/ToeLeft.dae.stl"/>
      </geometry>
    </collision>
  </link>
  <link name="right_foot_x">
    <inertial>
      <mass value="1"/>
      <origin xyz="0 0 0"/>
      <inertia ixx="1.0" ixy="0.0" ixz="0.0" iyy="1.0" iyz="0.0" izz="1.0"/>
    </inertial>
  </link>
  <link name="right_foot_y">
    <inertial>
      <mass value="1"/>
      <origin xyz="0 0 0"/>
      <inertia ixx="1.0" ixy="0.0" ixz="0.0" iyy="1.0" iyz="0.0" izz="1.0"/>
    </inertial>
  </link>
  <link name="right_foot_z">
    <inertial>
      <mass value="1"/>
      <origin xyz="0 0 0"/>
      <inertia ixx="1.0" ixy="0.0" ixz="0.0" iyy="1.0" iyz="0.0" izz="1.0"/>
    </inertial>
    <visual>
      <origin rpy="0 0 0" xyz="0 0 0"/>
      <geometry>
        <mesh filename="package://sherpa_spatial_relations/meshes/FootRight.dae"/>
      </geometry>
     <material name="Black"/>
    </visual>
    <collision>
      <origin rpy="0 0 0" xyz="0 0 0"/>
      <geometry>
        <mesh filename="package://sherpa_spatial_relations/meshes/FootRight.dae.stl"/>
      </geometry>
    </collision>
  </link>
  <link name="right_toe_x">
    <inertial>
      <mass value="1"/>
      <origin xyz="0 0 0"/>
      <inertia ixx="1.0" ixy="0.0" ixz="0.0" iyy="1.0" iyz="0.0" izz="1.0"/>
    </inertial>
  </link>
  <link name="right_toe_y">
    <inertial>
      <mass value="1"/>
      <origin xyz="0 0 0"/>
      <inertia ixx="1.0" ixy="0.0" ixz="0.0" iyy="1.0" iyz="0.0" izz="1.0"/>
    </inertial>
  </link>
  <link name="right_toe_z">
    <inertial>
      <mass value="1"/>
      <origin xyz="0 0 0"/>
      <inertia ixx="1.0" ixy="0.0" ixz="0.0" iyy="1.0" iyz="0.0" izz="1.0"/>
    </inertial>
    <visual>
      <origin rpy="0 0 0" xyz="0 0 0"/>
      <geometry>
        <mesh filename="package://sherpa_spatial_relations/meshes/ToeRight.dae"/>
      </geometry>
 <material name="Black"/>
    </visual>
    <collision>
      <origin rpy="0 0 0" xyz="0 0 0"/>
      <geometry>
        <mesh filename="package://sherpa_spatial_relations/meshes/ToeRight.dae.stl"/>
      </geometry>
    </collision>
  </link>
  <joint name="left_upper_leg_joint_x" type="revolute">
    <parent link="pelvis_y"/>
    <child link="left_upper_leg_x"/>
    <origin rpy="3.14 0 0" xyz="0.079 0 0"/>
    <axis xyz="1 0 0"/>
    <dynamics damping="0.7"/>
    <limit effort="100" lower="-2" upper="2" velocity="10.0"/>
  </joint>
  <transmission name="trans_left_upper_leg_x">
    <type>transmission_interface/SimpleTransmission</type>
    <joint name="left_upper_leg_joint_x"/>
    <actuator name="left_upper_leg_motor_x">
      <hardwareInterface>PositionJointInterface</hardwareInterface>
      <mechanicalReduction>1</mechanicalReduction>
    </actuator>
  </transmission>
  <joint name="left_upper_leg_joint_z" type="revolute">
    <parent link="left_upper_leg_x"/>
    <child link="left_upper_leg_z"/>
    <origin rpy="0 0 0" xyz="0 0 0"/>
    <axis xyz="0 0 1"/>
    <dynamics damping="0.7"/>
    <limit effort="100" lower="-2" upper="2" velocity="10.0"/>
  </joint>
  <transmission name="trans_{name}_z">
    <type>transmission_interface/SimpleTransmission</type>
    <joint name="left_upper_leg_joint_z"/>
    <actuator name="left_upper_leg_motor_z">
      <hardwareInterface>PositionJointInterface</hardwareInterface>
      <mechanicalReduction>1</mechanicalReduction>
    </actuator>
  </transmission>
  <joint name="left_upper_leg_joint_y" type="revolute">
    <parent link="left_upper_leg_z"/>
    <child link="left_upper_leg_y"/>
    <origin rpy="0 0 0" xyz="0 0 0"/>
    <axis xyz="0 1 0"/>
    <dynamics damping="0.7"/>
    <limit effort="100" lower="-2" upper="2" velocity="10.0"/>
  </joint>
  <transmission name="trans_left_upper_leg_y">
    <type>transmission_interface/SimpleTransmission</type>
    <joint name="left_upper_leg_joint_y"/>
    <actuator name="left_upper_leg_motor_y">
      <hardwareInterface>PositionJointInterface</hardwareInterface>
      <mechanicalReduction>1</mechanicalReduction>
    </actuator>
  </transmission>
  <joint name="left_lower_leg_joint_x" type="revolute">
    <parent link="left_upper_leg_y"/>
    <child link="left_lower_leg_x"/>
    <origin rpy="0 0 0" xyz="0 0.41 0"/>
    <axis xyz="1 0 0"/>
    <dynamics damping="0.7"/>
    <limit effort="100" lower="-2" upper="2" velocity="10.0"/>
  </joint>
  <transmission name="trans_left_lower_leg_x">
    <type>transmission_interface/SimpleTransmission</type>
    <joint name="left_lower_leg_joint_x"/>
    <actuator name="left_lower_leg_motor_x">
      <hardwareInterface>PositionJointInterface</hardwareInterface>
      <mechanicalReduction>1</mechanicalReduction>
    </actuator>
  </transmission>
  <joint name="left_lower_leg_joint_z" type="revolute">
    <parent link="left_lower_leg_x"/>
    <child link="left_lower_leg_z"/>
    <origin rpy="0 0 0" xyz="0 0 0"/>
    <axis xyz="0 0 1"/>
    <dynamics damping="0.7"/>
    <limit effort="100" lower="-2" upper="2" velocity="10.0"/>
  </joint>
  <transmission name="trans_{name}_z">
    <type>transmission_interface/SimpleTransmission</type>
    <joint name="left_lower_leg_joint_z"/>
    <actuator name="left_lower_leg_motor_z">
      <hardwareInterface>PositionJointInterface</hardwareInterface>
      <mechanicalReduction>1</mechanicalReduction>
    </actuator>
  </transmission>
  <joint name="left_lower_leg_joint_y" type="revolute">
    <parent link="left_lower_leg_z"/>
    <child link="left_lower_leg_y"/>
    <origin rpy="0 0 0" xyz="0 0 0"/>
    <axis xyz="0 1 0"/>
    <dynamics damping="0.7"/>
    <limit effort="100" lower="-2" upper="2" velocity="10.0"/>
  </joint>
  <transmission name="trans_left_lower_leg_y">
    <type>transmission_interface/SimpleTransmission</type>
    <joint name="left_lower_leg_joint_y"/>
    <actuator name="left_lower_leg_motor_y">
      <hardwareInterface>PositionJointInterface</hardwareInterface>
      <mechanicalReduction>1</mechanicalReduction>
    </actuator>
  </transmission>
  <joint name="left_foot_joint_x" type="revolute">
    <parent link="left_lower_leg_y"/>
    <child link="left_foot_x"/>
    <origin rpy="-1.15 0 0" xyz="0. 0.4 0"/>
    <axis xyz="1 0 0"/>
    <dynamics damping="0.7"/>
    <limit effort="100" lower="-2" upper="2" velocity="10.0"/>
  </joint>
  <transmission name="trans_left_foot_x">
    <type>transmission_interface/SimpleTransmission</type>
    <joint name="left_foot_joint_x"/>
    <actuator name="left_foot_motor_x">
      <hardwareInterface>PositionJointInterface</hardwareInterface>
      <mechanicalReduction>1</mechanicalReduction>
    </actuator>
  </transmission>
  <joint name="left_foot_joint_z" type="revolute">
    <parent link="left_foot_x"/>
    <child link="left_foot_z"/>
    <origin rpy="0 0 0" xyz="0 0 0"/>
    <axis xyz="0 0 1"/>
    <dynamics damping="0.7"/>
    <limit effort="100" lower="-2" upper="2" velocity="10.0"/>
  </joint>
  <transmission name="trans_{name}_z">
    <type>transmission_interface/SimpleTransmission</type>
    <joint name="left_foot_joint_z"/>
    <actuator name="left_foot_motor_z">
      <hardwareInterface>PositionJointInterface</hardwareInterface>
      <mechanicalReduction>1</mechanicalReduction>
    </actuator>
  </transmission>
  <joint name="left_foot_joint_y" type="revolute">
    <parent link="left_foot_z"/>
    <child link="left_foot_y"/>
    <origin rpy="0 0 0" xyz="0 0 0"/>
    <axis xyz="0 1 0"/>
    <dynamics damping="0.7"/>
    <limit effort="100" lower="-2" upper="2" velocity="10.0"/>
  </joint>
  <transmission name="trans_left_foot_y">
    <type>transmission_interface/SimpleTransmission</type>
    <joint name="left_foot_joint_y"/>
    <actuator name="left_foot_motor_y">
      <hardwareInterface>PositionJointInterface</hardwareInterface>
      <mechanicalReduction>1</mechanicalReduction>
    </actuator>
  </transmission>
  <joint name="left_toe_joint_x" type="revolute">
    <parent link="left_foot_y"/>
    <child link="left_toe_x"/>
    <origin rpy="0 0 0" xyz="0 0.18 0"/>
    <axis xyz="1 0 0"/>
    <dynamics damping="0.7"/>
    <limit effort="100" lower="-2" upper="2" velocity="10.0"/>
  </joint>
  <transmission name="trans_left_toe_x">
    <type>transmission_interface/SimpleTransmission</type>
    <joint name="left_toe_joint_x"/>
    <actuator name="left_toe_motor_x">
      <hardwareInterface>PositionJointInterface</hardwareInterface>
      <mechanicalReduction>1</mechanicalReduction>
    </actuator>
  </transmission>
  <joint name="left_toe_joint_z" type="revolute">
    <parent link="left_toe_x"/>
    <child link="left_toe_z"/>
    <origin rpy="0 0 0" xyz="0 0 0"/>
    <axis xyz="0 0 1"/>
    <dynamics damping="0.7"/>
    <limit effort="100" lower="-2" upper="2" velocity="10.0"/>
  </joint>
  <transmission name="trans_{name}_z">
    <type>transmission_interface/SimpleTransmission</type>
    <joint name="left_toe_joint_z"/>
    <actuator name="left_toe_motor_z">
      <hardwareInterface>PositionJointInterface</hardwareInterface>
      <mechanicalReduction>1</mechanicalReduction>
    </actuator>
  </transmission>
  <joint name="left_toe_joint_y" type="revolute">
    <parent link="left_toe_z"/>
    <child link="left_toe_y"/>
    <origin rpy="0 0 0" xyz="0 0 0"/>
    <axis xyz="0 1 0"/>
    <dynamics damping="0.7"/>
    <limit effort="100" lower="-2" upper="2" velocity="10.0"/>
  </joint>
  <transmission name="trans_left_toe_y">
    <type>transmission_interface/SimpleTransmission</type>
    <joint name="left_toe_joint_y"/>
    <actuator name="left_toe_motor_y">
      <hardwareInterface>PositionJointInterface</hardwareInterface>
      <mechanicalReduction>1</mechanicalReduction>
    </actuator>
  </transmission>
  <gazebo>
    <plugin filename="libgazebo_ros_control.so" name="gazebo_ros_control">
      <!--FIXME I will need my own ROSCONTROL driver here -->
      <robotSimType>sherpa_rover_control/SherpaRoverHWSim</robotSimType>
      <!--robotSimType>sherpa_human_control/SherpaHumanHWSim</robotSimType-->
      <robotNamespace>/</robotNamespace>
    </plugin>
  </gazebo>
</robot>
